[2022-09-05T18:46:24.914+0000] {taskinstance.py:1171} INFO - Dependencies all met for <TaskInstance: dag_with_tasklow_api_v02.greet scheduled__2022-09-04T00:00:00+00:00 [queued]>
[2022-09-05T18:46:24.928+0000] {taskinstance.py:1171} INFO - Dependencies all met for <TaskInstance: dag_with_tasklow_api_v02.greet scheduled__2022-09-04T00:00:00+00:00 [queued]>
[2022-09-05T18:46:24.928+0000] {taskinstance.py:1368} INFO - 
--------------------------------------------------------------------------------
[2022-09-05T18:46:24.928+0000] {taskinstance.py:1369} INFO - Starting attempt 3 of 6
[2022-09-05T18:46:24.928+0000] {taskinstance.py:1370} INFO - 
--------------------------------------------------------------------------------
[2022-09-05T18:46:24.947+0000] {taskinstance.py:1389} INFO - Executing <Task(_PythonDecoratedOperator): greet> on 2022-09-04 00:00:00+00:00
[2022-09-05T18:46:24.951+0000] {standard_task_runner.py:52} INFO - Started process 5545 to run task
[2022-09-05T18:46:24.956+0000] {standard_task_runner.py:79} INFO - Running: ['***', 'tasks', 'run', 'dag_with_tasklow_api_v02', 'greet', 'scheduled__2022-09-04T00:00:00+00:00', '--job-id', '354', '--raw', '--subdir', 'DAGS_FOLDER/dag_with_taskflow_api.py', '--cfg-path', '/tmp/tmp33_m9kgq', '--error-file', '/tmp/tmpb8idqvqt']
[2022-09-05T18:46:24.956+0000] {standard_task_runner.py:80} INFO - Job 354: Subtask greet
[2022-09-05T18:46:25.034+0000] {task_command.py:371} INFO - Running <TaskInstance: dag_with_tasklow_api_v02.greet scheduled__2022-09-04T00:00:00+00:00 [running]> on host c033faf33c57
[2022-09-05T18:46:25.111+0000] {taskinstance.py:1902} ERROR - Task failed with exception
Traceback (most recent call last):
  File "/home/airflow/.local/lib/python3.7/site-packages/airflow/models/taskinstance.py", line 1463, in _run_raw_task
    self._execute_task_with_callbacks(context, test_mode)
  File "/home/airflow/.local/lib/python3.7/site-packages/airflow/models/taskinstance.py", line 1567, in _execute_task_with_callbacks
    task_orig = self.render_templates(context=context)
  File "/home/airflow/.local/lib/python3.7/site-packages/airflow/models/taskinstance.py", line 2225, in render_templates
    rendered_task = self.task.render_template_fields(context)
  File "/home/airflow/.local/lib/python3.7/site-packages/airflow/models/baseoperator.py", line 1188, in render_template_fields
    self._do_render_template_fields(self, self.template_fields, context, jinja_env, set())
  File "/home/airflow/.local/lib/python3.7/site-packages/airflow/utils/session.py", line 71, in wrapper
    return func(*args, session=session, **kwargs)
  File "/home/airflow/.local/lib/python3.7/site-packages/airflow/models/abstractoperator.py", line 347, in _do_render_template_fields
    seen_oids,
  File "/home/airflow/.local/lib/python3.7/site-packages/airflow/models/abstractoperator.py", line 403, in render_template
    return {key: self.render_template(value, context, jinja_env) for key, value in value.items()}
  File "/home/airflow/.local/lib/python3.7/site-packages/airflow/models/abstractoperator.py", line 403, in <dictcomp>
    return {key: self.render_template(value, context, jinja_env) for key, value in value.items()}
  File "/home/airflow/.local/lib/python3.7/site-packages/airflow/models/abstractoperator.py", line 393, in render_template
    return value.resolve(context)
  File "/home/airflow/.local/lib/python3.7/site-packages/airflow/utils/session.py", line 71, in wrapper
    return func(*args, session=session, **kwargs)
  File "/home/airflow/.local/lib/python3.7/site-packages/airflow/models/xcom_arg.py", line 153, in resolve
    f'XComArg result from {self.operator.task_id} at {context["ti"].dag_id} '
airflow.exceptions.AirflowException: XComArg result from get_name at dag_with_tasklow_api_v02 with key="first_name" is not found!
[2022-09-05T18:46:25.117+0000] {taskinstance.py:1412} INFO - Marking task as UP_FOR_RETRY. dag_id=dag_with_tasklow_api_v02, task_id=greet, execution_date=20220904T000000, start_date=20220905T184624, end_date=20220905T184625
[2022-09-05T18:46:25.131+0000] {standard_task_runner.py:97} ERROR - Failed to execute job 354 for task greet (XComArg result from get_name at dag_with_tasklow_api_v02 with key="first_name" is not found!; 5545)
[2022-09-05T18:46:25.172+0000] {local_task_job.py:156} INFO - Task exited with return code 1
[2022-09-05T18:46:25.211+0000] {local_task_job.py:279} INFO - 0 downstream tasks scheduled from follow-on schedule check
